<?xml version="1.0" ?>
<!-- =================================================================================== -->
<!-- |    This document was autogenerated by xacro from indy.urdf.xacro                | -->
<!-- |    EDITING THIS FILE BY HAND IS NOT RECOMMENDED                                 | -->
<!-- =================================================================================== -->
<robot name="indy">
  <material name="black">
    <color rgba="0.0 0.0 0.0 1.0"/>
  </material>
  <material name="blue">
    <color rgba="0.0 0.0 0.8 1.0"/>
  </material>
  <material name="green">
    <color rgba="0.0 0.8 0.0 1.0"/>
  </material>
  <material name="icon_green">
    <color rgba="0.596078431372549 0.7764705882352941 0.3843137254901961 1.0"/>
  </material>
  <material name="icon_grey">
    <color rgba="0.2 0.2 0.2 1.0"/>
  </material>
  <material name="indy_white">
    <color rgba="0.8941176470588236 0.8941176470588236 0.8941176470588236 1.0"/>
  </material>
  <material name="grey">
    <color rgba="0.2 0.2 0.2 1.0"/>
  </material>
  <material name="orange">
    <color rgba="1.0 0.4235294117647059 0.0392156862745098 1.0"/>
  </material>
  <material name="brown">
    <color rgba="0.8705882352941177 0.8117647058823529 0.7647058823529411 1.0"/>
  </material>
  <material name="red">
    <color rgba="0.8 0.0 0.0 1.0"/>
  </material>
  <material name="white">
    <color rgba="1.0 1.0 1.0 1.0"/>
  </material>
  <material name="metal">
    <color rgba="0.768627450980392 0.749019607843137 0.729411764705882 1"/>
  </material>
  <material name="metal_grey">
    <color rgba="0.501960784313725 0.501960784313725 0.501960784313725 1"/>
  </material>
  <material name="metal_white">
    <color rgba="0.866666666666667 0.866666666666667 0.890196078431373 1"/>
  </material>
  <link name="world"/>
  <link name="link0">
    <visual>
      <origin rpy="0 0 0" xyz="0 0 0"/>
      <geometry>
        <mesh filename="file:///home/user/indy-ros2/install/indy_description/share/indy_description/meshes/icon7l/visual/ICoN7L_0.stl"/>
      </geometry>
      <material name="icon_grey"/>
    </visual>
    <collision>
      <origin rpy="0 0 0" xyz="0 0 0"/>
      <geometry>
        <mesh filename="file:///home/user/indy-ros2/install/indy_description/share/indy_description/meshes/icon7l/collision/ICoN7L_0.stl"/>
      </geometry>
    </collision>
    <inertial>
      <mass value="13.983"/>
      <origin rpy="0 0 0" xyz="-0.039698                             -0.000351                             0.116082"/>
      <inertia ixx="0.124117765" ixy="-0.005004253" ixz="0.009885393" iyy="0.15823513" iyz="0.000775764" izz="0.132492148"/>
    </inertial>
  </link>
  <link name="link1">
    <visual>
      <origin rpy="0 0 0" xyz="0 0 0"/>
      <geometry>
        <mesh filename="file:///home/user/indy-ros2/install/indy_description/share/indy_description/meshes/icon7l/visual/ICoN7L_1.stl"/>
      </geometry>
      <material name="icon_green"/>
    </visual>
    <collision>
      <origin rpy="0 0 0" xyz="0 0 0"/>
      <geometry>
        <mesh filename="file:///home/user/indy-ros2/install/indy_description/share/indy_description/meshes/icon7l/collision/ICoN7L_1.stl"/>
      </geometry>
    </collision>
    <inertial>
      <mass value="10.239"/>
      <origin rpy="0 0 0" xyz="0.008706                             0.011857                             0.31177"/>
      <inertia ixx="0.125830442" ixy="0.00107533" ixz="0.008842376" iyy="0.100388385" iyz="0.009567497" izz="0.074821155"/>
    </inertial>
  </link>
  <link name="link2">
    <visual>
      <origin rpy="0 0 0" xyz="0 0 0"/>
      <geometry>
        <mesh filename="file:///home/user/indy-ros2/install/indy_description/share/indy_description/meshes/icon7l/visual/ICoN7L_2.stl"/>
      </geometry>
      <material name="icon_green"/>
    </visual>
    <collision>
      <origin rpy="0 0 0" xyz="0 0 0"/>
      <geometry>
        <mesh filename="file:///home/user/indy-ros2/install/indy_description/share/indy_description/meshes/icon7l/collision/ICoN7L_2.stl"/>
      </geometry>
    </collision>
    <inertial>
      <mass value="12.857"/>
      <origin rpy="0 0 0" xyz="0.018905                             0.010751                             0.52907"/>
      <inertia ixx="0.47402811" ixy="0.001330876" ixz="-0.007317385" iyy="0.47402811" iyz="-0.01507504" izz="0.067688417"/>
    </inertial>
  </link>
  <link name="link3">
    <visual>
      <origin rpy="0 0 0" xyz="0 0 0"/>
      <geometry>
        <mesh filename="file:///home/user/indy-ros2/install/indy_description/share/indy_description/meshes/icon7l/visual/ICoN7L_3.stl"/>
      </geometry>
      <material name="icon_green"/>
    </visual>
    <collision>
      <origin rpy="0 0 0" xyz="0 0 0"/>
      <geometry>
        <mesh filename="file:///home/user/indy-ros2/install/indy_description/share/indy_description/meshes/icon7l/collision/ICoN7L_3.stl"/>
      </geometry>
    </collision>
    <inertial>
      <mass value="7.462"/>
      <origin rpy="0 0 0" xyz="0.087499                             0.002591                             0.882243"/>
      <inertia ixx="0.02282968" ixy="-0.0014108" ixz="0.009353277" iyy="0.064272136" iyz="-0.000465127" izz="0.064616989"/>
    </inertial>
  </link>
  <link name="link4">
    <visual>
      <origin rpy="0 0 0" xyz="0 0 0"/>
      <geometry>
        <mesh filename="file:///home/user/indy-ros2/install/indy_description/share/indy_description/meshes/icon7l/visual/ICoN7L_4.stl"/>
      </geometry>
      <material name="icon_green"/>
    </visual>
    <collision>
      <origin rpy="0 0 0" xyz="0 0 0"/>
      <geometry>
        <mesh filename="file:///home/user/indy-ros2/install/indy_description/share/indy_description/meshes/icon7l/collision/ICoN7L_4.stl"/>
      </geometry>
    </collision>
    <inertial>
      <mass value="4.38"/>
      <origin rpy="0 0 0" xyz="0.342922                             0.002166                             0.898844"/>
      <inertia ixx="0.010498598" ixy="0.001429971" ixz="-0.000130935" iyy="0.02539347" iyz="-5.2802e-05" izz="0.026841168"/>
    </inertial>
  </link>
  <link name="link5">
    <visual>
      <origin rpy="0 0 0" xyz="0 0 0"/>
      <geometry>
        <mesh filename="file:///home/user/indy-ros2/install/indy_description/share/indy_description/meshes/icon7l/visual/ICoN7L_5.stl"/>
      </geometry>
      <material name="icon_grey"/>
    </visual>
    <collision>
      <origin rpy="0 0 0" xyz="0 0 0"/>
      <geometry>
        <mesh filename="file:///home/user/indy-ros2/install/indy_description/share/indy_description/meshes/icon7l/collision/ICoN7L_5.stl"/>
      </geometry>
    </collision>
    <inertial>
      <mass value="1.656"/>
      <origin rpy="0 0 0" xyz="0.478109                             0.001852                             0.898"/>
      <inertia ixx="0.001430553" ixy="-7.1769e-05" ixz="-1.76e-07" iyy="0.002069889" iyz="-4e-09" izz="0.002523407"/>
    </inertial>
  </link>
  <link name="link6">
    <visual>
      <origin rpy="0 0 0" xyz="0 0 0"/>
      <geometry>
        <mesh filename="file:///home/user/indy-ros2/install/indy_description/share/indy_description/meshes/icon7l/visual/ICoN7L_6.stl"/>
      </geometry>
      <material name="icon_grey"/>
    </visual>
    <collision>
      <origin rpy="0 0 0" xyz="0 0 0"/>
      <geometry>
        <mesh filename="file:///home/user/indy-ros2/install/indy_description/share/indy_description/meshes/icon7l/collision/ICoN7L_6.stl"/>
      </geometry>
    </collision>
    <inertial>
      <mass value="0.272"/>
      <origin rpy="0 0 0" xyz="0.53752                             1.7e-05                             0.898"/>
      <inertia ixx="0.000145396" ixy="1.9e-08" ixz="0.0" iyy="7.9816e-05" iyz="0.0" izz="7.7334e-05"/>
    </inertial>
  </link>
  <link name="tcp"/>
  <joint name="global" type="fixed">
    <origin rpy="0 0 0" xyz="0 0 0"/>
    <parent link="world"/>
    <child link="link0"/>
  </joint>
  <joint name="joint0" type="revolute">
    <parent link="link0"/>
    <child link="link1"/>
    <origin rpy="0.0                         0.0                         0.0" xyz="0.0                          0.0                          0.19825"/>
    <axis xyz="0 0 1"/>
    <dynamics damping="0.1" friction="10.0"/>
    <limit effort="431.97" lower="-2.9670597283903604" upper="2.9670597283903604" velocity="6.632251157578453"/>
  </joint>
  <joint name="joint1" type="revolute">
    <parent link="link1"/>
    <child link="link2"/>
    <origin rpy="-1.570796327                         0.0                         0.0" xyz="0.025                          0.0                          0.202"/>
    <axis xyz="0 0 -1"/>
    <dynamics damping="0.1" friction="10.0"/>
    <limit effort="431.97" lower="-1.7453292519943295" upper="2.356194490192345" velocity="5.585053606381854"/>
  </joint>
  <joint name="joint2" type="revolute">
    <parent link="link2"/>
    <child link="link3"/>
    <origin rpy="0.0                         0.0                         1.570796327" xyz="0.0                          -0.463                          0.0"/>
    <axis xyz="0 0 -1"/>
    <dynamics damping="0.1" friction="10.0"/>
    <limit effort="197.23" lower="-3.6651914291880923" upper="1.1519173063162575" velocity="6.806784082777885"/>
  </joint>
  <joint name="joint3" type="revolute">
    <parent link="link3"/>
    <child link="link4"/>
    <origin rpy="1.570796327                         1.570796327                         0.0" xyz="-0.035                          -0.182                          0.0"/>
    <axis xyz="0 0 1"/>
    <dynamics damping="0.1" friction="10.0"/>
    <limit effort="79.79" lower="-3.490658503988659" upper="3.490658503988659" velocity="8.552113334772216"/>
  </joint>
  <joint name="joint4" type="revolute">
    <parent link="link4"/>
    <child link="link5"/>
    <origin rpy="1.570796327                         0.0                         -1.570796327" xyz="0.0                          0.0                          0.25"/>
    <axis xyz="0 0 -1"/>
    <dynamics damping="0.1" friction="10.0"/>
    <limit effort="79.79" lower="-2.356194490192345" upper="2.356194490192345" velocity="9.861110273767961"/>
  </joint>
  <joint name="joint5" type="revolute">
    <parent link="link5"/>
    <child link="link6"/>
    <origin rpy="1.570796327                         1.570796327                         3.14159265" xyz="0.0                          0.089                          0.0"/>
    <axis xyz="0 0 1"/>
    <dynamics damping="0.1" friction="10.0"/>
    <limit effort="79.79" lower="-6.283185307179586" upper="6.283185307179586" velocity="14.224433403753785"/>
  </joint>
  <joint name="tcp" type="fixed">
    <parent link="link6"/>
    <child link="tcp"/>
    <origin rpy="0.0                         0.0                         0.0" xyz="0.0                          0.0                          0.0"/>
  </joint>
  <ros2_control name="indy" type="system">
    <hardware>
      <plugin>fake_components/GenericSystem</plugin>
      <!-- <param name="fake_sensor_commands">${fake_sensor_commands}</param> -->
      <param name="state_following_offset">0.0</param>
    </hardware>
    <joint name="joint0">
      <command_interface name="position">
        <param name="min">{-2*pi}</param>
        <param name="max">{2*pi}</param>
      </command_interface>
      <command_interface name="velocity">
        <param name="min">-3.15</param>
        <param name="max">3.15</param>
      </command_interface>
      <!-- <state_interface name="position"/> -->
      <state_interface name="position">
        <param name="initial_value">0.0</param>
      </state_interface>
      <!-- <state_interface name="velocity"/> -->
      <state_interface name="velocity">
        <param name="initial_value">0.0</param>
      </state_interface>
      <state_interface name="effort"/>
    </joint>
    <joint name="joint1">
      <command_interface name="position">
        <param name="min">{-2*pi}</param>
        <param name="max">{2*pi}</param>
      </command_interface>
      <command_interface name="velocity">
        <param name="min">-3.15</param>
        <param name="max">3.15</param>
      </command_interface>
      <!-- <state_interface name="position"/> -->
      <state_interface name="position">
        <param name="initial_value">0.0</param>
      </state_interface>
      <!-- <state_interface name="velocity"/> -->
      <state_interface name="velocity">
        <param name="initial_value">0.0</param>
      </state_interface>
      <state_interface name="effort"/>
    </joint>
    <joint name="joint2">
      <command_interface name="position">
        <param name="min">{-2*pi}</param>
        <param name="max">{2*pi}</param>
      </command_interface>
      <command_interface name="velocity">
        <param name="min">-3.15</param>
        <param name="max">3.15</param>
      </command_interface>
      <!-- <state_interface name="position"/> -->
      <state_interface name="position">
        <param name="initial_value">-1.57</param>
      </state_interface>
      <!-- <state_interface name="velocity"/> -->
      <state_interface name="velocity">
        <param name="initial_value">0.0</param>
      </state_interface>
      <state_interface name="effort"/>
    </joint>
    <joint name="joint3">
      <command_interface name="position">
        <param name="min">{-2*pi}</param>
        <param name="max">{2*pi}</param>
      </command_interface>
      <command_interface name="velocity">
        <param name="min">-3.15</param>
        <param name="max">3.15</param>
      </command_interface>
      <!-- <state_interface name="position"/> -->
      <state_interface name="position">
        <param name="initial_value">0.0</param>
      </state_interface>
      <!-- <state_interface name="velocity"/> -->
      <state_interface name="velocity">
        <param name="initial_value">0.0</param>
      </state_interface>
      <state_interface name="effort"/>
    </joint>
    <joint name="joint4">
      <command_interface name="position">
        <param name="min">{-2*pi}</param>
        <param name="max">{2*pi}</param>
      </command_interface>
      <command_interface name="velocity">
        <param name="min">-3.15</param>
        <param name="max">3.15</param>
      </command_interface>
      <!-- <state_interface name="position"/> -->
      <state_interface name="position">
        <param name="initial_value">-1.57</param>
      </state_interface>
      <!-- <state_interface name="velocity"/> -->
      <state_interface name="velocity">
        <param name="initial_value">0.0</param>
      </state_interface>
      <state_interface name="effort"/>
    </joint>
    <joint name="joint5">
      <command_interface name="position">
        <param name="min">{-2*pi}</param>
        <param name="max">{2*pi}</param>
      </command_interface>
      <command_interface name="velocity">
        <param name="min">-3.15</param>
        <param name="max">3.15</param>
      </command_interface>
      <!-- <state_interface name="position"/> -->
      <state_interface name="position">
        <param name="initial_value">0.0</param>
      </state_interface>
      <!-- <state_interface name="velocity"/> -->
      <state_interface name="velocity">
        <param name="initial_value">0.0</param>
      </state_interface>
      <state_interface name="effort"/>
    </joint>
  </ros2_control>
  <!-- Add URDF transmission elements (for ros_control) -->
  <!-- <xacro:indy_transmission prefix="${prefix}" hw_interface="${transmission_hw_interface}" indy_type="${indy_type}"/> -->
</robot>
