<?xml version="1.0" ?>
<!-- =================================================================================== -->
<!-- |    This document was autogenerated by xacro from indy.urdf.xacro                | -->
<!-- |    EDITING THIS FILE BY HAND IS NOT RECOMMENDED                                 | -->
<!-- =================================================================================== -->
<robot name="indy">
  <material name="black">
    <color rgba="0.0 0.0 0.0 1.0"/>
  </material>
  <material name="blue">
    <color rgba="0.0 0.0 0.8 1.0"/>
  </material>
  <material name="green">
    <color rgba="0.0 0.8 0.0 1.0"/>
  </material>
  <material name="icon_green">
    <color rgba="0.596078431372549 0.7764705882352941 0.3843137254901961 1.0"/>
  </material>
  <material name="icon_grey">
    <color rgba="0.2 0.2 0.2 1.0"/>
  </material>
  <material name="indy_white">
    <color rgba="0.8941176470588236 0.8941176470588236 0.8941176470588236 1.0"/>
  </material>
  <material name="grey">
    <color rgba="0.2 0.2 0.2 1.0"/>
  </material>
  <material name="orange">
    <color rgba="1.0 0.4235294117647059 0.0392156862745098 1.0"/>
  </material>
  <material name="brown">
    <color rgba="0.8705882352941177 0.8117647058823529 0.7647058823529411 1.0"/>
  </material>
  <material name="red">
    <color rgba="0.8 0.0 0.0 1.0"/>
  </material>
  <material name="white">
    <color rgba="1.0 1.0 1.0 1.0"/>
  </material>
  <material name="metal">
    <color rgba="0.768627450980392 0.749019607843137 0.729411764705882 1"/>
  </material>
  <material name="metal_grey">
    <color rgba="0.501960784313725 0.501960784313725 0.501960784313725 1"/>
  </material>
  <material name="metal_white">
    <color rgba="0.866666666666667 0.866666666666667 0.890196078431373 1"/>
  </material>
  <link name="world"/>
  <link name="link0">
    <visual>
      <origin rpy="0 0 0" xyz="0 0 0"/>
      <geometry>
        <mesh filename="file:///home/user/indy-ros2/install/indy_description/share/indy_description/meshes/nuri4s/visual/Nuri4s_0.stl"/>
      </geometry>
      <material name="indy_white"/>
    </visual>
    <collision>
      <origin rpy="0 0 0" xyz="0 0 0"/>
      <geometry>
        <mesh filename="file:///home/user/indy-ros2/install/indy_description/share/indy_description/meshes/nuri4s/collision/Nuri4s_0.stl"/>
      </geometry>
    </collision>
    <inertial>
      <mass value="2.861045494"/>
      <origin rpy="0 0 0" xyz="0.0012911922                             -1.60081e-05                             0.0486515775"/>
      <inertia ixx="0.0070515946" ixy="-7.167e-07" ixz="-0.0001734706" iyy="0.0068408935" iyz="2.4613e-06" izz="0.009567187"/>
    </inertial>
  </link>
  <link name="link1">
    <visual>
      <origin rpy="0 0 0" xyz="0 0 0"/>
      <geometry>
        <mesh filename="file:///home/user/indy-ros2/install/indy_description/share/indy_description/meshes/nuri4s/visual/Nuri4s_1.stl"/>
      </geometry>
      <material name="indy_white"/>
    </visual>
    <collision>
      <origin rpy="0 0 0" xyz="0 0 0"/>
      <geometry>
        <mesh filename="file:///home/user/indy-ros2/install/indy_description/share/indy_description/meshes/nuri4s/collision/Nuri4s_1.stl"/>
      </geometry>
    </collision>
    <inertial>
      <mass value="3.167175036"/>
      <origin rpy="0 0 0" xyz="1.1136e-05                             -0.007992137                             0.235842012"/>
      <inertia ixx="3.12e-08" ixy="0.0" ixz="0.0" iyy="3.07e-08" iyz="-2.2e-09" izz="5.9e-09"/>
    </inertial>
  </link>
  <link name="link2">
    <visual>
      <origin rpy="0 0 0" xyz="0 0 0"/>
      <geometry>
        <mesh filename="file:///home/user/indy-ros2/install/indy_description/share/indy_description/meshes/nuri4s/visual/Nuri4s_2.stl"/>
      </geometry>
      <material name="indy_white"/>
    </visual>
    <collision>
      <origin rpy="0 0 0" xyz="0 0 0"/>
      <geometry>
        <mesh filename="file:///home/user/indy-ros2/install/indy_description/share/indy_description/meshes/nuri4s/collision/Nuri4s_2.stl"/>
      </geometry>
    </collision>
    <inertial>
      <mass value="4.29096783"/>
      <origin rpy="0 0 0" xyz="0.016666103                             -0.069300915                             0.18467127"/>
      <inertia ixx="1.404e-07" ixy="4e-10" ixz="1.49e-08" iyy="1.404e-07" iyz="-2.6e-09" izz="1.26e-08"/>
    </inertial>
  </link>
  <link name="link3">
    <visual>
      <origin rpy="0 0 0" xyz="0 0 0"/>
      <geometry>
        <mesh filename="file:///home/user/indy-ros2/install/indy_description/share/indy_description/meshes/nuri4s/visual/Nuri4s_3.stl"/>
      </geometry>
      <material name="indy_white"/>
    </visual>
    <collision>
      <origin rpy="0 0 0" xyz="0 0 0"/>
      <geometry>
        <mesh filename="file:///home/user/indy-ros2/install/indy_description/share/indy_description/meshes/nuri4s/collision/Nuri4s_3.stl"/>
      </geometry>
    </collision>
    <inertial>
      <mass value="2.018198648"/>
      <origin rpy="0 0 0" xyz="0.024900208                             0.009985986                             0.083739181"/>
      <inertia ixx="2.1e-08" ixy="-5e-10" ixz="4e-09" iyy="2.17e-08" iyz="-1.7e-09" izz="4.3e-09"/>
    </inertial>
  </link>
  <link name="link4">
    <visual>
      <origin rpy="0 0 0" xyz="0 0 0"/>
      <geometry>
        <mesh filename="file:///home/user/indy-ros2/install/indy_description/share/indy_description/meshes/nuri4s/visual/Nuri4s_4.stl"/>
      </geometry>
      <material name="indy_white"/>
    </visual>
    <collision>
      <origin rpy="0 0 0" xyz="0 0 0"/>
      <geometry>
        <mesh filename="file:///home/user/indy-ros2/install/indy_description/share/indy_description/meshes/nuri4s/collision/Nuri4s_4.stl"/>
      </geometry>
    </collision>
    <inertial>
      <mass value="1.882223023"/>
      <origin rpy="0 0 0" xyz="-2.5487e-05                             -0.01092259                             -0.071267109"/>
      <inertia ixx="1.33e-08" ixy="0.0" ixz="0.0" iyy="1.25e-08" iyz="-1.4e-09" izz="2.8e-09"/>
    </inertial>
  </link>
  <link name="link5">
    <visual>
      <origin rpy="0 0 0" xyz="0 0 0"/>
      <geometry>
        <mesh filename="file:///home/user/indy-ros2/install/indy_description/share/indy_description/meshes/nuri4s/visual/Nuri4s_5.stl"/>
      </geometry>
      <material name="indy_white"/>
    </visual>
    <collision>
      <origin rpy="0 0 0" xyz="0 0 0"/>
      <geometry>
        <mesh filename="file:///home/user/indy-ros2/install/indy_description/share/indy_description/meshes/nuri4s/collision/Nuri4s_5.stl"/>
      </geometry>
    </collision>
    <inertial>
      <mass value="1.507185922"/>
      <origin rpy="0 0 0" xyz="2.911e-06                             0.029173125                             0.007018623"/>
      <inertia ixx="5e-09" ixy="0.0" ixz="0.0" iyy="2.6e-09" iyz="-3e-10" izz="3.9e-09"/>
    </inertial>
  </link>
  <link name="link6">
    <visual>
      <origin rpy="0 0 0" xyz="0 0 0"/>
      <geometry>
        <mesh filename="file:///home/user/indy-ros2/install/indy_description/share/indy_description/meshes/nuri4s/visual/Nuri4s_6.stl"/>
      </geometry>
      <material name="indy_white"/>
    </visual>
    <collision>
      <origin rpy="0 0 0" xyz="0 0 0"/>
      <geometry>
        <mesh filename="file:///home/user/indy-ros2/install/indy_description/share/indy_description/meshes/nuri4s/collision/Nuri4s_6.stl"/>
      </geometry>
    </collision>
    <inertial>
      <mass value="0.634034296"/>
      <origin rpy="0 0 0" xyz="7.2631e-05                             7.9047e-05                             -0.044852927"/>
      <inertia ixx="1e-09" ixy="0.0" ixz="0.0" iyy="1e-09" iyz="0.0" izz="4e-10"/>
    </inertial>
  </link>
  <link name="tcp"/>
  <joint name="global" type="fixed">
    <origin rpy="0 0 0" xyz="0 0 0"/>
    <parent link="world"/>
    <child link="link0"/>
  </joint>
  <joint name="joint0" type="revolute">
    <parent link="link0"/>
    <child link="link1"/>
    <origin rpy="0.0                         0.0                         0.0" xyz="0.0                          0.0                          0.09"/>
    <axis xyz="0 0 1"/>
    <dynamics damping="0.1" friction="10.0"/>
    <limit effort="431.97" lower="-6.283185307179586" upper="6.283185307179586" velocity="3.141592653589793"/>
  </joint>
  <joint name="joint1" type="revolute">
    <parent link="link1"/>
    <child link="link2"/>
    <origin rpy="1.570796327                         0.0                         0.0" xyz="0.0                          -0.04                          0.238"/>
    <axis xyz="0 0 -1"/>
    <dynamics damping="0.1" friction="10.0"/>
    <limit effort="431.97" lower="-2.705260340591211" upper="2.443460952792061" velocity="3.141592653589793"/>
  </joint>
  <joint name="joint2" type="revolute">
    <parent link="link2"/>
    <child link="link3"/>
    <origin rpy="0.0                         0.0                         0.0" xyz="0.05                          0.4                          0.0"/>
    <axis xyz="0 0 -1"/>
    <dynamics damping="0.1" friction="10.0"/>
    <limit effort="197.23" lower="-3.0543261909900767" upper="2.356194490192345" velocity="3.141592653589793"/>
  </joint>
  <joint name="joint3" type="revolute">
    <parent link="link3"/>
    <child link="link4"/>
    <origin rpy="-1.570796327                         0.0                         0.0" xyz="-0.05                          0.195                          -0.04"/>
    <axis xyz="0 0 1"/>
    <dynamics damping="0.1" friction="10.0"/>
    <limit effort="79.79" lower="-6.283185307179586" upper="6.283185307179586" velocity="3.141592653589793"/>
  </joint>
  <joint name="joint4" type="revolute">
    <parent link="link4"/>
    <child link="link5"/>
    <origin rpy="1.570796327                         0.0                         0.0" xyz="0.0                          0.07                          0.2050424"/>
    <axis xyz="0 0 -1"/>
    <dynamics damping="0.1" friction="10.0"/>
    <limit effort="79.79" lower="-6.283185307179586" upper="6.283185307179586" velocity="3.141592653589793"/>
  </joint>
  <joint name="joint5" type="revolute">
    <parent link="link5"/>
    <child link="link6"/>
    <origin rpy="-1.570796327                         0.0                         0.0" xyz="0.0                          0.075                          -0.066"/>
    <axis xyz="0 0 1"/>
    <dynamics damping="0.1" friction="10.0"/>
    <limit effort="79.79" lower="-6.283185307179586" upper="6.283185307179586" velocity="3.141592653589793"/>
  </joint>
  <joint name="tcp" type="fixed">
    <parent link="link6"/>
    <child link="tcp"/>
    <origin rpy="0.0                         0.0                         0.0" xyz="0.0                          0.0                          0.0285"/>
  </joint>
  <ros2_control name="indy" type="system">
    <hardware>
      <plugin>fake_components/GenericSystem</plugin>
      <!-- <param name="fake_sensor_commands">${fake_sensor_commands}</param> -->
      <param name="state_following_offset">0.0</param>
    </hardware>
    <joint name="joint0">
      <command_interface name="position">
        <param name="min">{-2*pi}</param>
        <param name="max">{2*pi}</param>
      </command_interface>
      <command_interface name="velocity">
        <param name="min">-3.15</param>
        <param name="max">3.15</param>
      </command_interface>
      <!-- <state_interface name="position"/> -->
      <state_interface name="position">
        <param name="initial_value">0.0</param>
      </state_interface>
      <!-- <state_interface name="velocity"/> -->
      <state_interface name="velocity">
        <param name="initial_value">0.0</param>
      </state_interface>
      <state_interface name="effort"/>
    </joint>
    <joint name="joint1">
      <command_interface name="position">
        <param name="min">{-2*pi}</param>
        <param name="max">{2*pi}</param>
      </command_interface>
      <command_interface name="velocity">
        <param name="min">-3.15</param>
        <param name="max">3.15</param>
      </command_interface>
      <!-- <state_interface name="position"/> -->
      <state_interface name="position">
        <param name="initial_value">0.0</param>
      </state_interface>
      <!-- <state_interface name="velocity"/> -->
      <state_interface name="velocity">
        <param name="initial_value">0.0</param>
      </state_interface>
      <state_interface name="effort"/>
    </joint>
    <joint name="joint2">
      <command_interface name="position">
        <param name="min">{-2*pi}</param>
        <param name="max">{2*pi}</param>
      </command_interface>
      <command_interface name="velocity">
        <param name="min">-3.15</param>
        <param name="max">3.15</param>
      </command_interface>
      <!-- <state_interface name="position"/> -->
      <state_interface name="position">
        <param name="initial_value">-1.57</param>
      </state_interface>
      <!-- <state_interface name="velocity"/> -->
      <state_interface name="velocity">
        <param name="initial_value">0.0</param>
      </state_interface>
      <state_interface name="effort"/>
    </joint>
    <joint name="joint3">
      <command_interface name="position">
        <param name="min">{-2*pi}</param>
        <param name="max">{2*pi}</param>
      </command_interface>
      <command_interface name="velocity">
        <param name="min">-3.15</param>
        <param name="max">3.15</param>
      </command_interface>
      <!-- <state_interface name="position"/> -->
      <state_interface name="position">
        <param name="initial_value">0.0</param>
      </state_interface>
      <!-- <state_interface name="velocity"/> -->
      <state_interface name="velocity">
        <param name="initial_value">0.0</param>
      </state_interface>
      <state_interface name="effort"/>
    </joint>
    <joint name="joint4">
      <command_interface name="position">
        <param name="min">{-2*pi}</param>
        <param name="max">{2*pi}</param>
      </command_interface>
      <command_interface name="velocity">
        <param name="min">-3.15</param>
        <param name="max">3.15</param>
      </command_interface>
      <!-- <state_interface name="position"/> -->
      <state_interface name="position">
        <param name="initial_value">-1.57</param>
      </state_interface>
      <!-- <state_interface name="velocity"/> -->
      <state_interface name="velocity">
        <param name="initial_value">0.0</param>
      </state_interface>
      <state_interface name="effort"/>
    </joint>
    <joint name="joint5">
      <command_interface name="position">
        <param name="min">{-2*pi}</param>
        <param name="max">{2*pi}</param>
      </command_interface>
      <command_interface name="velocity">
        <param name="min">-3.15</param>
        <param name="max">3.15</param>
      </command_interface>
      <!-- <state_interface name="position"/> -->
      <state_interface name="position">
        <param name="initial_value">0.0</param>
      </state_interface>
      <!-- <state_interface name="velocity"/> -->
      <state_interface name="velocity">
        <param name="initial_value">0.0</param>
      </state_interface>
      <state_interface name="effort"/>
    </joint>
  </ros2_control>
  <!-- Add URDF transmission elements (for ros_control) -->
  <!-- <xacro:indy_transmission prefix="${prefix}" hw_interface="${transmission_hw_interface}" indy_type="${indy_type}"/> -->
</robot>
