<?xml version="1.0" ?>
<!-- =================================================================================== -->
<!-- |    This document was autogenerated by xacro from indy.urdf.xacro                | -->
<!-- |    EDITING THIS FILE BY HAND IS NOT RECOMMENDED                                 | -->
<!-- =================================================================================== -->
<robot name="indy">
  <material name="black">
    <color rgba="0.0 0.0 0.0 1.0"/>
  </material>
  <material name="blue">
    <color rgba="0.0 0.0 0.8 1.0"/>
  </material>
  <material name="green">
    <color rgba="0.0 0.8 0.0 1.0"/>
  </material>
  <material name="icon_green">
    <color rgba="0.596078431372549 0.7764705882352941 0.3843137254901961 1.0"/>
  </material>
  <material name="icon_grey">
    <color rgba="0.2 0.2 0.2 1.0"/>
  </material>
  <material name="indy_white">
    <color rgba="0.8941176470588236 0.8941176470588236 0.8941176470588236 1.0"/>
  </material>
  <material name="grey">
    <color rgba="0.2 0.2 0.2 1.0"/>
  </material>
  <material name="orange">
    <color rgba="1.0 0.4235294117647059 0.0392156862745098 1.0"/>
  </material>
  <material name="brown">
    <color rgba="0.8705882352941177 0.8117647058823529 0.7647058823529411 1.0"/>
  </material>
  <material name="red">
    <color rgba="0.8 0.0 0.0 1.0"/>
  </material>
  <material name="white">
    <color rgba="1.0 1.0 1.0 1.0"/>
  </material>
  <material name="metal">
    <color rgba="0.768627450980392 0.749019607843137 0.729411764705882 1"/>
  </material>
  <material name="metal_grey">
    <color rgba="0.501960784313725 0.501960784313725 0.501960784313725 1"/>
  </material>
  <material name="metal_white">
    <color rgba="0.866666666666667 0.866666666666667 0.890196078431373 1"/>
  </material>
  <link name="world"/>
  <link name="body_base">
    <visual>
      <origin rpy="0 0 0" xyz="0 0 0"/>
      <geometry>
        <mesh filename="file:///home/user/indy-ros2/install/indy_description/share/indy_description/meshes/dual_icon3/visual/Body_base.stl"/>
      </geometry>
      <material name="icon_grey"/>
    </visual>
    <collision>
      <origin rpy="0 0 0" xyz="0 0 0"/>
      <geometry>
        <mesh filename="file:///home/user/indy-ros2/install/indy_description/share/indy_description/meshes/dual_icon3/collision/Body_base.stl"/>
      </geometry>
    </collision>
    <inertial>
      <mass value="5.726"/>
      <origin rpy="0 0 0" xyz="0.0                             0.0                             0.008986"/>
      <inertia ixx="0.024968" ixy="0.0" ixz="0.0" iyy="0.024968" iyz="0.0" izz="0.047968"/>
    </inertial>
  </link>
  <link name="body_frame">
    <visual>
      <origin rpy="0 0 0" xyz="0 0 0"/>
      <geometry>
        <mesh filename="file:///home/user/indy-ros2/install/indy_description/share/indy_description/meshes/dual_icon3/visual/Body_frame.stl"/>
      </geometry>
      <material name="icon_grey"/>
    </visual>
    <collision>
      <origin rpy="0 0 0" xyz="0 0 0"/>
      <geometry>
        <mesh filename="file:///home/user/indy-ros2/install/indy_description/share/indy_description/meshes/dual_icon3/collision/Body_frame.stl"/>
      </geometry>
    </collision>
    <inertial>
      <mass value="23.464"/>
      <origin rpy="0 0 0" xyz="0.001336                             0.017855                             0.261572"/>
      <inertia ixx="4.565827" ixy="0.0" ixz="-0.031929" iyy="4.67275" iyz="-2.7e-05" izz="0.233592"/>
    </inertial>
  </link>
  <link name="body_cover">
    <visual>
      <origin rpy="0 0 0" xyz="0 0 0"/>
      <geometry>
        <mesh filename="file:///home/user/indy-ros2/install/indy_description/share/indy_description/meshes/dual_icon3/visual/Body_cover.stl"/>
      </geometry>
      <material name="indy_white"/>
    </visual>
    <collision>
      <origin rpy="0 0 0" xyz="0 0 0"/>
      <geometry>
        <mesh filename="file:///home/user/indy-ros2/install/indy_description/share/indy_description/meshes/dual_icon3/collision/Body_cover.stl"/>
      </geometry>
    </collision>
    <inertial>
      <mass value="61.443"/>
      <origin rpy="0 0 0" xyz="-0.012687                             0.008506                             0.411406"/>
      <inertia ixx="10.164663" ixy="8e-05" ixz="-0.355422" iyy="9.509362" iyz="0.00149" izz="2.004066"/>
    </inertial>
  </link>
  <link name="left_arm_link0">
    <visual>
      <origin rpy="0 0 0" xyz="0 0 0"/>
      <geometry>
        <mesh filename="file:///home/user/indy-ros2/install/indy_description/share/indy_description/meshes/icon3/visual/ICoN3_0.stl"/>
      </geometry>
      <material name="icon_grey"/>
    </visual>
    <collision>
      <origin rpy="0 0 0" xyz="0 0 0"/>
      <geometry>
        <mesh filename="file:///home/user/indy-ros2/install/indy_description/share/indy_description/meshes/icon3/collision/ICoN3_0.stl"/>
      </geometry>
    </collision>
    <inertial>
      <mass value="6.568"/>
      <origin rpy="0 0 0" xyz="-0.033213                             -0.001385                             0.101897"/>
      <inertia ixx="0.036615476" ixy="-0.002034665" ixz="0.005558115" iyy="0.045081494" iyz="0.000178649" izz="0.032810217"/>
    </inertial>
  </link>
  <link name="left_arm_link1">
    <visual>
      <origin rpy="0 0 0" xyz="0 0 0"/>
      <geometry>
        <mesh filename="file:///home/user/indy-ros2/install/indy_description/share/indy_description/meshes/icon3/visual/ICoN3_1.stl"/>
      </geometry>
      <material name="icon_green"/>
    </visual>
    <collision>
      <origin rpy="0 0 0" xyz="0 0 0"/>
      <geometry>
        <mesh filename="file:///home/user/indy-ros2/install/indy_description/share/indy_description/meshes/icon3/collision/ICoN3_1.stl"/>
      </geometry>
    </collision>
    <inertial>
      <mass value="2.983"/>
      <origin rpy="0 0 0" xyz="0.001336                             0.017855                             0.261572"/>
      <inertia ixx="0.02585624" ixy="-0.000122011" ixz="-0.000122978" iyy="0.018711126" iyz="0.004101675" izz="0.014823463"/>
    </inertial>
  </link>
  <link name="left_arm_link2">
    <visual>
      <origin rpy="0 0 0" xyz="0 0 0"/>
      <geometry>
        <mesh filename="file:///home/user/indy-ros2/install/indy_description/share/indy_description/meshes/icon3/visual/ICoN3_2.stl"/>
      </geometry>
      <material name="icon_green"/>
    </visual>
    <collision>
      <origin rpy="0 0 0" xyz="0 0 0"/>
      <geometry>
        <mesh filename="file:///home/user/indy-ros2/install/indy_description/share/indy_description/meshes/icon3/collision/ICoN3_2.stl"/>
      </geometry>
    </collision>
    <inertial>
      <mass value="5.667"/>
      <origin rpy="0 0 0" xyz="-0.012687                             0.008506                             0.411406"/>
      <inertia ixx="0.059807757" ixy="4.9409e-05" ixz="-0.002553581" iyy="0.0514891" iyz="-0.000795126" izz="0.020935533"/>
    </inertial>
  </link>
  <link name="left_arm_link3">
    <visual>
      <origin rpy="0 0 0" xyz="0 0 0"/>
      <geometry>
        <mesh filename="file:///home/user/indy-ros2/install/indy_description/share/indy_description/meshes/icon3/visual/ICoN3_3.stl"/>
      </geometry>
      <material name="icon_green"/>
    </visual>
    <collision>
      <origin rpy="0 0 0" xyz="0 0 0"/>
      <geometry>
        <mesh filename="file:///home/user/indy-ros2/install/indy_description/share/indy_description/meshes/icon3/collision/ICoN3_3.stl"/>
      </geometry>
    </collision>
    <inertial>
      <mass value="2.922"/>
      <origin rpy="0 0 0" xyz="-0.007513                             0.016906                             0.583953"/>
      <inertia ixx="0.007076576" ixy="0.000361564" ixz="0.000669577" iyy="0.005617412" iyz="0.000302648" izz="0.007241272"/>
    </inertial>
  </link>
  <link name="left_arm_link4">
    <visual>
      <origin rpy="0 0 0" xyz="0 0 0"/>
      <geometry>
        <mesh filename="file:///home/user/indy-ros2/install/indy_description/share/indy_description/meshes/icon3/visual/ICoN3_4.stl"/>
      </geometry>
      <material name="icon_green"/>
    </visual>
    <collision>
      <origin rpy="0 0 0" xyz="0 0 0"/>
      <geometry>
        <mesh filename="file:///home/user/indy-ros2/install/indy_description/share/indy_description/meshes/icon3/collision/ICoN3_4.stl"/>
      </geometry>
    </collision>
    <inertial>
      <mass value="3.269"/>
      <origin rpy="0 0 0" xyz="0.150496                             -0.00038                             0.609627"/>
      <inertia ixx="0.003834949" ixy="-0.000143086" ixz="-9.3784e-05" iyy="0.021384314" iyz="1.1847e-05" izz="0.021676984"/>
    </inertial>
  </link>
  <link name="left_arm_link5">
    <visual>
      <origin rpy="0 0 0" xyz="0 0 0"/>
      <geometry>
        <mesh filename="file:///home/user/indy-ros2/install/indy_description/share/indy_description/meshes/icon3/visual/ICoN3_5.stl"/>
      </geometry>
      <material name="icon_grey"/>
    </visual>
    <collision>
      <origin rpy="0 0 0" xyz="0 0 0"/>
      <geometry>
        <mesh filename="file:///home/user/indy-ros2/install/indy_description/share/indy_description/meshes/icon3/collision/ICoN3_5.stl"/>
      </geometry>
    </collision>
    <inertial>
      <mass value="1.67"/>
      <origin rpy="0 0 0" xyz="0.319227                             0.001458                             0.610932"/>
      <inertia ixx="0.000116129" ixy="-4.9576e-05" ixz="7.08e-07" iyy="0.001960741" iyz="1.193e-06" izz="0.001997393"/>
    </inertial>
  </link>
  <link name="left_arm_link6">
    <visual>
      <origin rpy="0 0 0" xyz="0 0 0"/>
      <geometry>
        <mesh filename="file:///home/user/indy-ros2/install/indy_description/share/indy_description/meshes/icon3/visual/ICoN3_6.stl"/>
      </geometry>
      <material name="icon_grey"/>
    </visual>
    <collision>
      <origin rpy="0 0 0" xyz="0 0 0"/>
      <geometry>
        <mesh filename="file:///home/user/indy-ros2/install/indy_description/share/indy_description/meshes/icon3/collision/ICoN3_6.stl"/>
      </geometry>
    </collision>
    <inertial>
      <mass value="0.272"/>
      <origin rpy="0 0 0" xyz="0.0                             0.0                             0.0"/>
      <inertia ixx="0.000145396" ixy="1.9e-08" ixz="0.0" iyy="7.9816e-05" iyz="0.0" izz="7.7334e-05"/>
    </inertial>
  </link>
  <link name="right_arm_link0">
    <visual>
      <origin rpy="0 0 0" xyz="0 0 0"/>
      <geometry>
        <mesh filename="file:///home/user/indy-ros2/install/indy_description/share/indy_description/meshes/icon3/visual/ICoN3_0.stl"/>
      </geometry>
      <material name="icon_grey"/>
    </visual>
    <collision>
      <origin rpy="0 0 0" xyz="0 0 0"/>
      <geometry>
        <mesh filename="file:///home/user/indy-ros2/install/indy_description/share/indy_description/meshes/icon3/collision/ICoN3_0.stl"/>
      </geometry>
    </collision>
    <inertial>
      <mass value="6.568"/>
      <origin rpy="0 0 0" xyz="-0.033213                             -0.001385                             0.101897"/>
      <inertia ixx="0.036615476" ixy="-0.002034665" ixz="0.005558115" iyy="0.045081494" iyz="0.000178649" izz="0.032810217"/>
    </inertial>
  </link>
  <link name="right_arm_link1">
    <visual>
      <origin rpy="0 0 0" xyz="0 0 0"/>
      <geometry>
        <mesh filename="file:///home/user/indy-ros2/install/indy_description/share/indy_description/meshes/icon3/visual/ICoN3_1.stl"/>
      </geometry>
      <material name="icon_green"/>
    </visual>
    <collision>
      <origin rpy="0 0 0" xyz="0 0 0"/>
      <geometry>
        <mesh filename="file:///home/user/indy-ros2/install/indy_description/share/indy_description/meshes/icon3/collision/ICoN3_1.stl"/>
      </geometry>
    </collision>
    <inertial>
      <mass value="2.983"/>
      <origin rpy="0 0 0" xyz="0.001336                             0.017855                             0.261572"/>
      <inertia ixx="0.02585624" ixy="-0.000122011" ixz="-0.000122978" iyy="0.018711126" iyz="0.004101675" izz="0.014823463"/>
    </inertial>
  </link>
  <link name="right_arm_link2">
    <visual>
      <origin rpy="0 0 0" xyz="0 0 0"/>
      <geometry>
        <mesh filename="file:///home/user/indy-ros2/install/indy_description/share/indy_description/meshes/icon3/visual/ICoN3_2.stl"/>
      </geometry>
      <material name="icon_green"/>
    </visual>
    <collision>
      <origin rpy="0 0 0" xyz="0 0 0"/>
      <geometry>
        <mesh filename="file:///home/user/indy-ros2/install/indy_description/share/indy_description/meshes/icon3/collision/ICoN3_2.stl"/>
      </geometry>
    </collision>
    <inertial>
      <mass value="5.667"/>
      <origin rpy="0 0 0" xyz="-0.012687                             0.008506                             0.411406"/>
      <inertia ixx="0.059807757" ixy="4.9409e-05" ixz="-0.002553581" iyy="0.0514891" iyz="-0.000795126" izz="0.020935533"/>
    </inertial>
  </link>
  <link name="right_arm_link3">
    <visual>
      <origin rpy="0 0 0" xyz="0 0 0"/>
      <geometry>
        <mesh filename="file:///home/user/indy-ros2/install/indy_description/share/indy_description/meshes/icon3/visual/ICoN3_3.stl"/>
      </geometry>
      <material name="icon_green"/>
    </visual>
    <collision>
      <origin rpy="0 0 0" xyz="0 0 0"/>
      <geometry>
        <mesh filename="file:///home/user/indy-ros2/install/indy_description/share/indy_description/meshes/icon3/collision/ICoN3_3.stl"/>
      </geometry>
    </collision>
    <inertial>
      <mass value="2.922"/>
      <origin rpy="0 0 0" xyz="-0.007513                             0.016906                             0.583953"/>
      <inertia ixx="0.007076576" ixy="0.000361564" ixz="0.000669577" iyy="0.005617412" iyz="0.000302648" izz="0.007241272"/>
    </inertial>
  </link>
  <link name="right_arm_link4">
    <visual>
      <origin rpy="0 0 0" xyz="0 0 0"/>
      <geometry>
        <mesh filename="file:///home/user/indy-ros2/install/indy_description/share/indy_description/meshes/icon3/visual/ICoN3_4.stl"/>
      </geometry>
      <material name="icon_green"/>
    </visual>
    <collision>
      <origin rpy="0 0 0" xyz="0 0 0"/>
      <geometry>
        <mesh filename="file:///home/user/indy-ros2/install/indy_description/share/indy_description/meshes/icon3/collision/ICoN3_4.stl"/>
      </geometry>
    </collision>
    <inertial>
      <mass value="3.269"/>
      <origin rpy="0 0 0" xyz="0.150496                             -0.00038                             0.609627"/>
      <inertia ixx="0.003834949" ixy="-0.000143086" ixz="-9.3784e-05" iyy="0.021384314" iyz="1.1847e-05" izz="0.021676984"/>
    </inertial>
  </link>
  <link name="right_arm_link5">
    <visual>
      <origin rpy="0 0 0" xyz="0 0 0"/>
      <geometry>
        <mesh filename="file:///home/user/indy-ros2/install/indy_description/share/indy_description/meshes/icon3/visual/ICoN3_5.stl"/>
      </geometry>
      <material name="icon_grey"/>
    </visual>
    <collision>
      <origin rpy="0 0 0" xyz="0 0 0"/>
      <geometry>
        <mesh filename="file:///home/user/indy-ros2/install/indy_description/share/indy_description/meshes/icon3/collision/ICoN3_5.stl"/>
      </geometry>
    </collision>
    <inertial>
      <mass value="1.67"/>
      <origin rpy="0 0 0" xyz="0.319227                             0.001458                             0.610932"/>
      <inertia ixx="0.000116129" ixy="-4.9576e-05" ixz="7.08e-07" iyy="0.001960741" iyz="1.193e-06" izz="0.001997393"/>
    </inertial>
  </link>
  <link name="right_arm_link6">
    <visual>
      <origin rpy="0 0 0" xyz="0 0 0"/>
      <geometry>
        <mesh filename="file:///home/user/indy-ros2/install/indy_description/share/indy_description/meshes/icon3/visual/ICoN3_6.stl"/>
      </geometry>
      <material name="icon_grey"/>
    </visual>
    <collision>
      <origin rpy="0 0 0" xyz="0 0 0"/>
      <geometry>
        <mesh filename="file:///home/user/indy-ros2/install/indy_description/share/indy_description/meshes/icon3/collision/ICoN3_6.stl"/>
      </geometry>
    </collision>
    <inertial>
      <mass value="0.272"/>
      <origin rpy="0 0 0" xyz="0.0                             0.0                             0.0"/>
      <inertia ixx="0.000145396" ixy="1.9e-08" ixz="0.0" iyy="7.9816e-05" iyz="0.0" izz="7.7334e-05"/>
    </inertial>
  </link>
  <link name="left_arm_tcp"/>
  <link name="right_arm_tcp"/>
  <joint name="global" type="fixed">
    <origin rpy="0 0 0" xyz="0 0 0"/>
    <parent link="world"/>
    <child link="body_base"/>
  </joint>
  <joint name="base_frame" type="revolute">
    <parent link="body_base"/>
    <child link="body_frame"/>
    <origin rpy="0.0                         0.0                         0.0" xyz="0.0                          0.0                          0.0285"/>
    <axis xyz="0 0 1"/>
    <dynamics damping="0.1" friction="10.0"/>
    <limit effort="1000.0" lower="-3.141592653589793" upper="3.141592653589793" velocity="10.0"/>
  </joint>
  <joint name="frame_cover" type="fixed">
    <parent link="body_frame"/>
    <child link="body_cover"/>
    <origin rpy="0.0                         0.0                         0.0" xyz="0.0                          0.0                          0.0116"/>
  </joint>
  <joint name="left_arm_connect" type="fixed">
    <parent link="body_frame"/>
    <child link="left_arm_link0"/>
    <origin rpy="-1.570796327                         0.0                         -0.261799388" xyz="0.011367                          0.042157                          0.541659"/>
  </joint>
  <joint name="right_arm_connect" type="fixed">
    <parent link="body_frame"/>
    <child link="right_arm_link0"/>
    <origin rpy="1.570796327                         0.0                         0.261799388" xyz="0.011367                          -0.042157                          0.541659"/>
  </joint>
  <joint name="left_arm_joint0" type="revolute">
    <parent link="left_arm_link0"/>
    <child link="left_arm_link1"/>
    <origin rpy="0.0                         0.0                         0.0" xyz="0.0                          0.0                          0.156"/>
    <axis xyz="0 0 1"/>
    <dynamics damping="0.1" friction="10.0"/>
    <limit effort="431.97" lower="-2.9670597283903604" upper="2.9670597283903604" velocity="7.853981633974483"/>
  </joint>
  <joint name="left_arm_joint1" type="revolute">
    <parent link="left_arm_link1"/>
    <child link="left_arm_link2"/>
    <origin rpy="1.570796327                         0.0                         3.14159265" xyz="0.0                          0.0                          0.174"/>
    <axis xyz="0 0 1"/>
    <dynamics damping="0.1" friction="10.0"/>
    <limit effort="431.97" lower="-1.9198621771937625" upper="2.0943951023931953" velocity="7.853981633974483"/>
  </joint>
  <joint name="left_arm_joint2" type="revolute">
    <parent link="left_arm_link2"/>
    <child link="left_arm_link3"/>
    <origin rpy="0.0                         0.0                         1.570796327" xyz="0.0                          0.26                          0.0"/>
    <axis xyz="0 0 1"/>
    <dynamics damping="0.1" friction="10.0"/>
    <limit effort="197.23" lower="-3.4557519189487724" upper="1.0821041362364843" velocity="9.16297857297023"/>
  </joint>
  <joint name="left_arm_joint3" type="revolute">
    <parent link="left_arm_link3"/>
    <child link="left_arm_link4"/>
    <origin rpy="-1.570796327                         1.570796327                         0.0" xyz="0.021                          0.0625                          0.0"/>
    <axis xyz="0 0 1"/>
    <dynamics damping="0.1" friction="10.0"/>
    <limit effort="79.79" lower="-3.490658503988659" upper="3.490658503988659" velocity="10.471975511965978"/>
  </joint>
  <joint name="left_arm_joint4" type="revolute">
    <parent link="left_arm_link4"/>
    <child link="left_arm_link5"/>
    <origin rpy="1.570796327                         -1.570796327                         -1.570796327" xyz="0.0                          0.0                          0.237"/>
    <axis xyz="0 0 1"/>
    <dynamics damping="0.1" friction="10.0"/>
    <limit effort="79.79" lower="-2.059488517353309" upper="2.059488517353309" velocity="10.471975511965978"/>
  </joint>
  <joint name="left_arm_joint5" type="revolute">
    <parent link="left_arm_link5"/>
    <child link="left_arm_link6"/>
    <origin rpy="1.570796327                         0.0                         1.570796327" xyz="0.0685                          0.0                          0.0"/>
    <axis xyz="0 0 1"/>
    <dynamics damping="0.1" friction="10.0"/>
    <limit effort="79.79" lower="-6.1086523819801535" upper="6.1086523819801535" velocity="13.962634015954636"/>
  </joint>
  <joint name="left_arm_tcp" type="fixed">
    <parent link="left_arm_link6"/>
    <child link="left_arm_tcp"/>
    <origin rpy="0.0                         0.0                         0.0" xyz="0.0                          0.0                          0.0"/>
  </joint>
  <joint name="right_arm_joint0" type="revolute">
    <parent link="right_arm_link0"/>
    <child link="right_arm_link1"/>
    <origin rpy="0.0                         0.0                         0.0" xyz="0.0                          0.0                          0.156"/>
    <axis xyz="0 0 1"/>
    <dynamics damping="0.1" friction="10.0"/>
    <limit effort="431.97" lower="-2.9670597283903604" upper="2.9670597283903604" velocity="7.853981633974483"/>
  </joint>
  <joint name="right_arm_joint1" type="revolute">
    <parent link="right_arm_link1"/>
    <child link="right_arm_link2"/>
    <origin rpy="1.570796327                         0.0                         3.14159265" xyz="0.0                          0.0                          0.174"/>
    <axis xyz="0 0 1"/>
    <dynamics damping="0.1" friction="10.0"/>
    <limit effort="431.97" lower="-1.9198621771937625" upper="2.0943951023931953" velocity="7.853981633974483"/>
  </joint>
  <joint name="right_arm_joint2" type="revolute">
    <parent link="right_arm_link2"/>
    <child link="right_arm_link3"/>
    <origin rpy="0.0                         0.0                         1.570796327" xyz="0.0                          0.26                          0.0"/>
    <axis xyz="0 0 1"/>
    <dynamics damping="0.1" friction="10.0"/>
    <limit effort="197.23" lower="-3.4557519189487724" upper="1.0821041362364843" velocity="9.16297857297023"/>
  </joint>
  <joint name="right_arm_joint3" type="revolute">
    <parent link="right_arm_link3"/>
    <child link="right_arm_link4"/>
    <origin rpy="-1.570796327                         1.570796327                         0.0" xyz="0.021                          0.0625                          0.0"/>
    <axis xyz="0 0 1"/>
    <dynamics damping="0.1" friction="10.0"/>
    <limit effort="79.79" lower="-3.490658503988659" upper="3.490658503988659" velocity="10.471975511965978"/>
  </joint>
  <joint name="right_arm_joint4" type="revolute">
    <parent link="right_arm_link4"/>
    <child link="right_arm_link5"/>
    <origin rpy="1.570796327                         -1.570796327                         -1.570796327" xyz="0.0                          0.0                          0.237"/>
    <axis xyz="0 0 1"/>
    <dynamics damping="0.1" friction="10.0"/>
    <limit effort="79.79" lower="-2.059488517353309" upper="2.059488517353309" velocity="10.471975511965978"/>
  </joint>
  <joint name="right_arm_joint5" type="revolute">
    <parent link="right_arm_link5"/>
    <child link="right_arm_link6"/>
    <origin rpy="1.570796327                         0.0                         1.570796327" xyz="0.0685                          0.0                          0.0"/>
    <axis xyz="0 0 1"/>
    <dynamics damping="0.1" friction="10.0"/>
    <limit effort="79.79" lower="-6.1086523819801535" upper="6.1086523819801535" velocity="13.962634015954636"/>
  </joint>
  <joint name="right_arm_tcp" type="fixed">
    <parent link="right_arm_link6"/>
    <child link="right_arm_tcp"/>
    <origin rpy="0.0                         0.0                         0.0" xyz="0.0                          0.0                          0.0"/>
  </joint>
  <ros2_control name="indy" type="system">
    <hardware>
      <plugin>fake_components/GenericSystem</plugin>
      <!-- <param name="fake_sensor_commands">${fake_sensor_commands}</param> -->
      <param name="state_following_offset">0.0</param>
    </hardware>
    <joint name="joint0">
      <command_interface name="position">
        <param name="min">{-2*pi}</param>
        <param name="max">{2*pi}</param>
      </command_interface>
      <command_interface name="velocity">
        <param name="min">-3.15</param>
        <param name="max">3.15</param>
      </command_interface>
      <!-- <state_interface name="position"/> -->
      <state_interface name="position">
        <param name="initial_value">0.0</param>
      </state_interface>
      <!-- <state_interface name="velocity"/> -->
      <state_interface name="velocity">
        <param name="initial_value">0.0</param>
      </state_interface>
      <state_interface name="effort"/>
    </joint>
    <joint name="joint1">
      <command_interface name="position">
        <param name="min">{-2*pi}</param>
        <param name="max">{2*pi}</param>
      </command_interface>
      <command_interface name="velocity">
        <param name="min">-3.15</param>
        <param name="max">3.15</param>
      </command_interface>
      <!-- <state_interface name="position"/> -->
      <state_interface name="position">
        <param name="initial_value">0.0</param>
      </state_interface>
      <!-- <state_interface name="velocity"/> -->
      <state_interface name="velocity">
        <param name="initial_value">0.0</param>
      </state_interface>
      <state_interface name="effort"/>
    </joint>
    <joint name="joint2">
      <command_interface name="position">
        <param name="min">{-2*pi}</param>
        <param name="max">{2*pi}</param>
      </command_interface>
      <command_interface name="velocity">
        <param name="min">-3.15</param>
        <param name="max">3.15</param>
      </command_interface>
      <!-- <state_interface name="position"/> -->
      <state_interface name="position">
        <param name="initial_value">-1.57</param>
      </state_interface>
      <!-- <state_interface name="velocity"/> -->
      <state_interface name="velocity">
        <param name="initial_value">0.0</param>
      </state_interface>
      <state_interface name="effort"/>
    </joint>
    <joint name="joint3">
      <command_interface name="position">
        <param name="min">{-2*pi}</param>
        <param name="max">{2*pi}</param>
      </command_interface>
      <command_interface name="velocity">
        <param name="min">-3.15</param>
        <param name="max">3.15</param>
      </command_interface>
      <!-- <state_interface name="position"/> -->
      <state_interface name="position">
        <param name="initial_value">0.0</param>
      </state_interface>
      <!-- <state_interface name="velocity"/> -->
      <state_interface name="velocity">
        <param name="initial_value">0.0</param>
      </state_interface>
      <state_interface name="effort"/>
    </joint>
    <joint name="joint4">
      <command_interface name="position">
        <param name="min">{-2*pi}</param>
        <param name="max">{2*pi}</param>
      </command_interface>
      <command_interface name="velocity">
        <param name="min">-3.15</param>
        <param name="max">3.15</param>
      </command_interface>
      <!-- <state_interface name="position"/> -->
      <state_interface name="position">
        <param name="initial_value">-1.57</param>
      </state_interface>
      <!-- <state_interface name="velocity"/> -->
      <state_interface name="velocity">
        <param name="initial_value">0.0</param>
      </state_interface>
      <state_interface name="effort"/>
    </joint>
    <joint name="joint5">
      <command_interface name="position">
        <param name="min">{-2*pi}</param>
        <param name="max">{2*pi}</param>
      </command_interface>
      <command_interface name="velocity">
        <param name="min">-3.15</param>
        <param name="max">3.15</param>
      </command_interface>
      <!-- <state_interface name="position"/> -->
      <state_interface name="position">
        <param name="initial_value">0.0</param>
      </state_interface>
      <!-- <state_interface name="velocity"/> -->
      <state_interface name="velocity">
        <param name="initial_value">0.0</param>
      </state_interface>
      <state_interface name="effort"/>
    </joint>
  </ros2_control>
  <!-- Add URDF transmission elements (for ros_control) -->
  <!-- <xacro:indy_transmission prefix="${prefix}" hw_interface="${transmission_hw_interface}" indy_type="${indy_type}"/> -->
</robot>
