<?xml version="1.0" ?>
<!-- =================================================================================== -->
<!-- |    This document was autogenerated by xacro from indy.urdf.xacro                | -->
<!-- |    EDITING THIS FILE BY HAND IS NOT RECOMMENDED                                 | -->
<!-- =================================================================================== -->
<robot name="indy">
  <material name="black">
    <color rgba="0.0 0.0 0.0 1.0"/>
  </material>
  <material name="blue">
    <color rgba="0.0 0.0 0.8 1.0"/>
  </material>
  <material name="green">
    <color rgba="0.0 0.8 0.0 1.0"/>
  </material>
  <material name="icon_green">
    <color rgba="0.596078431372549 0.7764705882352941 0.3843137254901961 1.0"/>
  </material>
  <material name="icon_grey">
    <color rgba="0.2 0.2 0.2 1.0"/>
  </material>
  <material name="indy_white">
    <color rgba="0.8941176470588236 0.8941176470588236 0.8941176470588236 1.0"/>
  </material>
  <material name="grey">
    <color rgba="0.2 0.2 0.2 1.0"/>
  </material>
  <material name="orange">
    <color rgba="1.0 0.4235294117647059 0.0392156862745098 1.0"/>
  </material>
  <material name="brown">
    <color rgba="0.8705882352941177 0.8117647058823529 0.7647058823529411 1.0"/>
  </material>
  <material name="red">
    <color rgba="0.8 0.0 0.0 1.0"/>
  </material>
  <material name="white">
    <color rgba="1.0 1.0 1.0 1.0"/>
  </material>
  <material name="metal">
    <color rgba="0.768627450980392 0.749019607843137 0.729411764705882 1"/>
  </material>
  <material name="metal_grey">
    <color rgba="0.501960784313725 0.501960784313725 0.501960784313725 1"/>
  </material>
  <material name="metal_white">
    <color rgba="0.866666666666667 0.866666666666667 0.890196078431373 1"/>
  </material>
  <link name="world"/>
  <link name="link0">
    <visual>
      <origin rpy="0 0 0" xyz="0 0 0"/>
      <geometry>
        <mesh filename="file:///home/user/indy-ros2/install/indy_description/share/indy_description/meshes/nuri20c/visual/Nuri20c_0.stl"/>
      </geometry>
      <material name="indy_white"/>
    </visual>
    <collision>
      <origin rpy="0 0 0" xyz="0 0 0"/>
      <geometry>
        <mesh filename="file:///home/user/indy-ros2/install/indy_description/share/indy_description/meshes/nuri20c/collision/Nuri20c_0.stl"/>
      </geometry>
    </collision>
    <inertial>
      <mass value="10.512390866"/>
      <origin rpy="0 0 0" xyz="-0.010310153                             0.000780291                             0.083318232"/>
      <inertia ixx="0.308514702" ixy="0.000125597" ixz="0.000393993" iyy="0.250711665" iyz="-0.089236308" izz="0.15494443"/>
    </inertial>
  </link>
  <link name="link1">
    <visual>
      <origin rpy="0 0 0" xyz="0 0 0"/>
      <geometry>
        <mesh filename="file:///home/user/indy-ros2/install/indy_description/share/indy_description/meshes/nuri20c/visual/Nuri20c_1.stl"/>
      </geometry>
      <material name="indy_white"/>
    </visual>
    <collision>
      <origin rpy="0 0 0" xyz="0 0 0"/>
      <geometry>
        <mesh filename="file:///home/user/indy-ros2/install/indy_description/share/indy_description/meshes/nuri20c/collision/Nuri20c_1.stl"/>
      </geometry>
    </collision>
    <inertial>
      <mass value="18.195720206"/>
      <origin rpy="0 0 0" xyz="0.000240331                             -0.054540577                             0.274633037"/>
      <inertia ixx="3.464049922" ixy="-0.000562113" ixz="0.00073117" iyy="3.440234068" iyz="-0.042986656" izz="0.157533551"/>
    </inertial>
  </link>
  <link name="link2">
    <visual>
      <origin rpy="0 0 0" xyz="0 0 0"/>
      <geometry>
        <mesh filename="file:///home/user/indy-ros2/install/indy_description/share/indy_description/meshes/nuri20c/visual/Nuri20c_2.stl"/>
      </geometry>
      <material name="indy_white"/>
    </visual>
    <collision>
      <origin rpy="0 0 0" xyz="0 0 0"/>
      <geometry>
        <mesh filename="file:///home/user/indy-ros2/install/indy_description/share/indy_description/meshes/nuri20c/collision/Nuri20c_2.stl"/>
      </geometry>
    </collision>
    <inertial>
      <mass value="22.845886455"/>
      <origin rpy="0 0 0" xyz="0.000350858                             -0.222504834                             0.392300733"/>
      <inertia ixx="0.392300733" ixy="5.896e-06" ixz="0.034805416" iyy="0.111550655" iyz="0.067247963" izz="0.076018726"/>
    </inertial>
  </link>
  <link name="link3">
    <visual>
      <origin rpy="0 0 0" xyz="0 0 0"/>
      <geometry>
        <mesh filename="file:///home/user/indy-ros2/install/indy_description/share/indy_description/meshes/nuri20c/visual/Nuri20c_3.stl"/>
      </geometry>
      <material name="indy_white"/>
    </visual>
    <collision>
      <origin rpy="0 0 0" xyz="0 0 0"/>
      <geometry>
        <mesh filename="file:///home/user/indy-ros2/install/indy_description/share/indy_description/meshes/nuri20c/collision/Nuri20c_3.stl"/>
      </geometry>
    </collision>
    <inertial>
      <mass value="7.83830585"/>
      <origin rpy="0 0 0" xyz="1.1068e-05                             0.072653038                             0.060501825"/>
      <inertia ixx="0.060501825" ixy="2.2514e-05" ixz="0.024288356" iyy="0.367218603" iyz="0.022510592" izz="0.36403022"/>
    </inertial>
  </link>
  <link name="link4">
    <visual>
      <origin rpy="0 0 0" xyz="0 0 0"/>
      <geometry>
        <mesh filename="file:///home/user/indy-ros2/install/indy_description/share/indy_description/meshes/nuri20c/visual/Nuri20c_4.stl"/>
      </geometry>
      <material name="indy_white"/>
    </visual>
    <collision>
      <origin rpy="0 0 0" xyz="0 0 0"/>
      <geometry>
        <mesh filename="file:///home/user/indy-ros2/install/indy_description/share/indy_description/meshes/nuri20c/collision/Nuri20c_4.stl"/>
      </geometry>
    </collision>
    <inertial>
      <mass value="6.943393986"/>
      <origin rpy="0 0 0" xyz="-4.8663e-05                             -0.012031009                             -0.294370638"/>
      <inertia ixx="0.016980216" ixy="-6.525e-06" ixz="1.1833e-05" iyy="0.010158127" iyz="0.001464221" izz="0.012000093"/>
    </inertial>
  </link>
  <link name="link5">
    <visual>
      <origin rpy="0 0 0" xyz="0 0 0"/>
      <geometry>
        <mesh filename="file:///home/user/indy-ros2/install/indy_description/share/indy_description/meshes/nuri20c/visual/Nuri20c_5.stl"/>
      </geometry>
      <material name="indy_white"/>
    </visual>
    <collision>
      <origin rpy="0 0 0" xyz="0 0 0"/>
      <geometry>
        <mesh filename="file:///home/user/indy-ros2/install/indy_description/share/indy_description/meshes/nuri20c/collision/Nuri20c_5.stl"/>
      </geometry>
    </collision>
    <inertial>
      <mass value="3.229294314"/>
      <origin rpy="0 0 0" xyz="6.5407e-05                             0.037815201                             0.018830826"/>
      <inertia ixx="0.003408808" ixy="-5.94e-07" ixz="1.907e-06" iyy="0.003419538" iyz="-1.072e-06" izz="0.002022276"/>
    </inertial>
  </link>
  <link name="link6">
    <visual>
      <origin rpy="0 0 0" xyz="0 0 0"/>
      <geometry>
        <mesh filename="file:///home/user/indy-ros2/install/indy_description/share/indy_description/meshes/nuri20c/visual/Nuri20c_6.stl"/>
      </geometry>
      <material name="indy_white"/>
    </visual>
    <collision>
      <origin rpy="0 0 0" xyz="0 0 0"/>
      <geometry>
        <mesh filename="file:///home/user/indy-ros2/install/indy_description/share/indy_description/meshes/nuri20c/collision/Nuri20c_6.stl"/>
      </geometry>
    </collision>
    <inertial>
      <mass value="1.586348204"/>
      <origin rpy="0 0 0" xyz="-3.1443e-05                             5.1657e-05                             -0.052799124"/>
      <inertia ixx="0.0" ixy="0.0" ixz="0.0" iyy="0.0" iyz="0.0" izz="0.0"/>
    </inertial>
  </link>
  <link name="tcp"/>
  <joint name="global" type="fixed">
    <origin rpy="0 0 0" xyz="0 0 0"/>
    <parent link="world"/>
    <child link="link0"/>
  </joint>
  <joint name="joint0" type="revolute">
    <parent link="link0"/>
    <child link="link1"/>
    <origin rpy="0.0                         0.0                         0.0" xyz="0.0                          0.0                          0.079"/>
    <axis xyz="0 0 1"/>
    <dynamics damping="0.1" friction="10.0"/>
    <limit effort="431.97" lower="-6.283185307179586" upper="6.283185307179586" velocity="3.141592653589793"/>
  </joint>
  <joint name="joint1" type="revolute">
    <parent link="link1"/>
    <child link="link2"/>
    <origin rpy="1.570796327                         0.0                         0.0" xyz="0.0                          -0.12                          0.288"/>
    <axis xyz="0 0 -1"/>
    <dynamics damping="0.1" friction="10.0"/>
    <limit effort="431.97" lower="-2.705260340591211" upper="2.443460952792061" velocity="3.141592653589793"/>
  </joint>
  <joint name="joint2" type="revolute">
    <parent link="link2"/>
    <child link="link3"/>
    <origin rpy="0.0                         0.0                         0.0" xyz="0.0                          0.9                          0.0"/>
    <axis xyz="0 0 1"/>
    <dynamics damping="0.1" friction="10.0"/>
    <limit effort="197.23" lower="-3.0543261909900767" upper="2.356194490192345" velocity="3.141592653589793"/>
  </joint>
  <joint name="joint3" type="revolute">
    <parent link="link3"/>
    <child link="link4"/>
    <origin rpy="-1.570796327                         0.0                         0.0" xyz="0.0                          0.22                          -0.12"/>
    <axis xyz="0 0 1"/>
    <dynamics damping="0.1" friction="10.0"/>
    <limit effort="79.79" lower="-6.283185307179586" upper="6.283185307179586" velocity="3.141592653589793"/>
  </joint>
  <joint name="joint4" type="revolute">
    <parent link="link4"/>
    <child link="link5"/>
    <origin rpy="1.570796327                         0.0                         0.0" xyz="0.0                          0.11                          0.53"/>
    <axis xyz="0 0 1"/>
    <dynamics damping="0.1" friction="10.0"/>
    <limit effort="79.79" lower="-6.283185307179586" upper="6.283185307179586" velocity="3.141592653589793"/>
  </joint>
  <joint name="joint5" type="revolute">
    <parent link="link5"/>
    <child link="link6"/>
    <origin rpy="-1.570796327                         0.0                         0.0" xyz="0.0                          0.1                          -0.06"/>
    <axis xyz="0 0 1"/>
    <dynamics damping="0.1" friction="10.0"/>
    <limit effort="79.79" lower="-6.283185307179586" upper="6.283185307179586" velocity="3.141592653589793"/>
  </joint>
  <joint name="tcp" type="fixed">
    <parent link="link6"/>
    <child link="tcp"/>
    <origin rpy="0.0                         0.0                         0.0" xyz="0.0                          0.0                          0.04"/>
  </joint>
  <ros2_control name="indy" type="system">
    <hardware>
      <plugin>fake_components/GenericSystem</plugin>
      <!-- <param name="fake_sensor_commands">${fake_sensor_commands}</param> -->
      <param name="state_following_offset">0.0</param>
    </hardware>
    <joint name="joint0">
      <command_interface name="position">
        <param name="min">{-2*pi}</param>
        <param name="max">{2*pi}</param>
      </command_interface>
      <command_interface name="velocity">
        <param name="min">-3.15</param>
        <param name="max">3.15</param>
      </command_interface>
      <!-- <state_interface name="position"/> -->
      <state_interface name="position">
        <param name="initial_value">0.0</param>
      </state_interface>
      <!-- <state_interface name="velocity"/> -->
      <state_interface name="velocity">
        <param name="initial_value">0.0</param>
      </state_interface>
      <state_interface name="effort"/>
    </joint>
    <joint name="joint1">
      <command_interface name="position">
        <param name="min">{-2*pi}</param>
        <param name="max">{2*pi}</param>
      </command_interface>
      <command_interface name="velocity">
        <param name="min">-3.15</param>
        <param name="max">3.15</param>
      </command_interface>
      <!-- <state_interface name="position"/> -->
      <state_interface name="position">
        <param name="initial_value">0.0</param>
      </state_interface>
      <!-- <state_interface name="velocity"/> -->
      <state_interface name="velocity">
        <param name="initial_value">0.0</param>
      </state_interface>
      <state_interface name="effort"/>
    </joint>
    <joint name="joint2">
      <command_interface name="position">
        <param name="min">{-2*pi}</param>
        <param name="max">{2*pi}</param>
      </command_interface>
      <command_interface name="velocity">
        <param name="min">-3.15</param>
        <param name="max">3.15</param>
      </command_interface>
      <!-- <state_interface name="position"/> -->
      <state_interface name="position">
        <param name="initial_value">-1.57</param>
      </state_interface>
      <!-- <state_interface name="velocity"/> -->
      <state_interface name="velocity">
        <param name="initial_value">0.0</param>
      </state_interface>
      <state_interface name="effort"/>
    </joint>
    <joint name="joint3">
      <command_interface name="position">
        <param name="min">{-2*pi}</param>
        <param name="max">{2*pi}</param>
      </command_interface>
      <command_interface name="velocity">
        <param name="min">-3.15</param>
        <param name="max">3.15</param>
      </command_interface>
      <!-- <state_interface name="position"/> -->
      <state_interface name="position">
        <param name="initial_value">0.0</param>
      </state_interface>
      <!-- <state_interface name="velocity"/> -->
      <state_interface name="velocity">
        <param name="initial_value">0.0</param>
      </state_interface>
      <state_interface name="effort"/>
    </joint>
    <joint name="joint4">
      <command_interface name="position">
        <param name="min">{-2*pi}</param>
        <param name="max">{2*pi}</param>
      </command_interface>
      <command_interface name="velocity">
        <param name="min">-3.15</param>
        <param name="max">3.15</param>
      </command_interface>
      <!-- <state_interface name="position"/> -->
      <state_interface name="position">
        <param name="initial_value">-1.57</param>
      </state_interface>
      <!-- <state_interface name="velocity"/> -->
      <state_interface name="velocity">
        <param name="initial_value">0.0</param>
      </state_interface>
      <state_interface name="effort"/>
    </joint>
    <joint name="joint5">
      <command_interface name="position">
        <param name="min">{-2*pi}</param>
        <param name="max">{2*pi}</param>
      </command_interface>
      <command_interface name="velocity">
        <param name="min">-3.15</param>
        <param name="max">3.15</param>
      </command_interface>
      <!-- <state_interface name="position"/> -->
      <state_interface name="position">
        <param name="initial_value">0.0</param>
      </state_interface>
      <!-- <state_interface name="velocity"/> -->
      <state_interface name="velocity">
        <param name="initial_value">0.0</param>
      </state_interface>
      <state_interface name="effort"/>
    </joint>
  </ros2_control>
  <!-- Add URDF transmission elements (for ros_control) -->
  <!-- <xacro:indy_transmission prefix="${prefix}" hw_interface="${transmission_hw_interface}" indy_type="${indy_type}"/> -->
</robot>
